<?xml version="1.0" encoding="utf-8"?>
<!-- This URDF was automatically created by SolidWorks to URDF Exporter! Originally created by Stephen Brawner (brawner@gmail.com) 
     Commit Version: 1.5.1-0-g916b5db  Build Version: 1.5.7152.31018
     For more information, please see http://wiki.ros.org/sw_urdf_exporter -->
<robot
  name="wheelball">
  <link
    name="base_link">
    <inertial>
      <origin
        xyz="0.000885138044595191 0.0915699924718767 -0.0157912683455384"
        rpy="0 0 0" />
      <mass
        value="5.32485366509133" />
      <inertia
        ixx="0.0219378727233068"
        ixy="-4.01751561825444E-06"
        ixz="-1.47975198130989E-06"
        iyy="0.0232029020939229"
        iyz="-8.06521337684411E-06"
        izz="0.0149048926646327" />
    </inertial>
    <visual>
      <origin
        xyz="0 0 0"
        rpy="0 0 0" />
      <geometry>
        <mesh
          filename="package://wheelball/meshes/base_link.STL" />
      </geometry>
      <material
        name="">
        <color
          rgba="0.752941176470588 0.752941176470588 0.752941176470588 1" />
      </material>
    </visual>
    <collision>
      <origin
        xyz="0 0 0"
        rpy="0 0 0" />
      <geometry>
        <mesh
          filename="package://wheelball/meshes/base_link.STL" />
      </geometry>
    </collision>
  </link>
  <link
    name="RFS">
    <inertial>
      <origin
        xyz="0.0724473276378503 -0.00242306558271334 -0.0667549990091164"
        rpy="0 0 0" />
      <mass
        value="0.26437001106024" />
      <inertia
        ixx="3.20746276473134E-05"
        ixy="1.44118283521328E-07"
        ixz="6.30853084344763E-08"
        iyy="6.22704126338856E-05"
        iyz="-2.01894652764198E-07"
        izz="6.28519936954001E-05" />
    </inertial>
    <visual>
      <origin
        xyz="0 0 0"
        rpy="0 0 0" />
      <geometry>
        <mesh
          filename="package://wheelball/meshes/RFS.STL" />
      </geometry>
      <material
        name="">
        <color
          rgba="0.752941176470588 0.752941176470588 0.752941176470588 1" />
      </material>
    </visual>
    <collision>
      <origin
        xyz="0 0 0"
        rpy="0 0 0" />
      <geometry>
        <mesh
          filename="package://wheelball/meshes/RFS.STL" />
      </geometry>
    </collision>
  </link>
  <joint
    name="RFS"
    type="fixed">
    <origin
      xyz="-0.21292 -0.11437 -0.037202"
      rpy="2.834 0 0" />
    <parent
      link="base_link" />
    <child
      link="RFS" />
    <axis
      xyz="0 0 0" />
    <limit
      lower="0"
      upper="0"
      effort="0"
      velocity="0" />
  </joint>
  <link
    name="RFW">
    <inertial>
      <origin
        xyz="0.014171 0 -1.3878E-17"
        rpy="0 0 0" />
      <mass
        value="0.23877" />
      <inertia
        ixx="0.00029907"
        ixy="-3.9717E-37"
        ixz="7.3408E-37"
        iyy="0.00016737"
        iyz="-8.4703E-22"
        izz="0.00016737" />
    </inertial>
    <visual>
      <origin
        xyz="0 0 0"
        rpy="0 0 0" />
      <geometry>
        <mesh
          filename="package://wheelball/meshes/RFW.STL" />
      </geometry>
      <material
        name="">
        <color
          rgba="1 1 1 1" />
      </material>
    </visual>
    <collision>
      <origin
        xyz="0 0 0"
        rpy="0 0 0" />
      <geometry>
        <mesh
          filename="package://wheelball/meshes/RFW.STL" />
      </geometry>
    </collision>
  </link>
  <joint
    name="RFW"
    type="continuous">
    <origin
      xyz="0 0.00097405 -0.03369"
      rpy="-1.3077 0 0" />
    <parent
      link="RFS" />
    <child
      link="RFW" />
    <axis
      xyz="1 0 0" />
    <limit
      effort="3.1"
      velocity="7" />
  </joint>
  <link
    name="LFS">
    <inertial>
      <origin
        xyz="0.0666875210853817 0.00364278355332748 -0.0648369138582874"
        rpy="0 0 0" />
      <mass
        value="0.26437001106024" />
      <inertia
        ixx="3.20746276473134E-05"
        ixy="-1.4411828352132E-07"
        ixz="-6.30853084344762E-08"
        iyy="6.22704126338856E-05"
        iyz="-2.01894652764187E-07"
        izz="6.28519936954001E-05" />
    </inertial>
    <visual>
      <origin
        xyz="0 0 0"
        rpy="0 0 0" />
      <geometry>
        <mesh
          filename="package://wheelball/meshes/LFS.STL" />
      </geometry>
      <material
        name="">
        <color
          rgba="0.752941176470588 0.752941176470588 0.752941176470588 1" />
      </material>
    </visual>
    <collision>
      <origin
        xyz="0 0 0"
        rpy="0 0 0" />
      <geometry>
        <mesh
          filename="package://wheelball/meshes/LFS.STL" />
      </geometry>
    </collision>
  </link>
  <joint
    name="LFS"
    type="fixed">
    <origin
      xyz="0.20716 -0.075688 -0.037202"
      rpy="2.834 0 3.1416" />
    <parent
      link="base_link" />
    <child
      link="LFS" />
    <axis
      xyz="0 0 0" />
    <limit
      lower="0"
      upper="0"
      effort="0"
      velocity="0" />
  </joint>
  <link
    name="LFW">
    <inertial>
      <origin
        xyz="-0.00841099113507679 -1.38777878078145E-17 0"
        rpy="0 0 0" />
      <mass
        value="0.238771211024828" />
      <inertia
        ixx="0.000299070391410013"
        ixy="3.54440352668465E-22"
        ixz="-1.84333746845529E-21"
        iyy="0.000167368400731884"
        iyz="6.7762635780344E-21"
        izz="0.000167368400731884" />
    </inertial>
    <visual>
      <origin
        xyz="0 0 0"
        rpy="0 0 0" />
      <geometry>
        <mesh
          filename="package://wheelball/meshes/LFW.STL" />
      </geometry>
      <material
        name="">
        <color
          rgba="1 1 1 1" />
      </material>
    </visual>
    <collision>
      <origin
        xyz="0 0 0"
        rpy="0 0 0" />
      <geometry>
        <mesh
          filename="package://wheelball/meshes/LFW.STL" />
      </geometry>
    </collision>
  </link>
  <joint
    name="LFW"
    type="continuous">
    <origin
      xyz="0 -0.018219 -0.039786"
      rpy="-0.026787 0 3.1416" />
    <parent
      link="LFS" />
    <child
      link="LFW" />
    <axis
      xyz="1 0 0" />
    <limit
      effort="3.1"
      velocity="7" />
  </joint>
  <link
    name="RBS">
    <inertial>
      <origin
        xyz="-0.00678676998851023 0.0106702734987945 0.0591953733266077"
        rpy="0 0 0" />
      <mass
        value="0.11410709738518" />
      <inertia
        ixx="7.89414159986181E-05"
        ixy="5.55241337234204E-22"
        ixz="1.14721099197346E-06"
        iyy="5.15117788979022E-05"
        iyz="5.87979936265405E-21"
        izz="7.8389894275756E-05" />
    </inertial>
    <visual>
      <origin
        xyz="0 0 0"
        rpy="0 0 0" />
      <geometry>
        <mesh
          filename="package://wheelball/meshes/RBS.STL" />
      </geometry>
      <material
        name="">
        <color
          rgba="0.752941176470588 0.752941176470588 0.752941176470588 1" />
      </material>
    </visual>
    <collision>
      <origin
        xyz="0 0 0"
        rpy="0 0 0" />
      <geometry>
        <mesh
          filename="package://wheelball/meshes/RBS.STL" />
      </geometry>
    </collision>
  </link>
  <joint
    name="RBS"
    type="fixed">
    <origin
      xyz="-0.23339 0.12116 0"
      rpy="-1.5708 0 -2.2503" />
    <parent
      link="base_link" />
    <child
      link="RBS" />
    <axis
      xyz="0 0 0" />
    <limit
      lower="0"
      upper="0"
      effort="0"
      velocity="0" />
  </joint>
  <link
    name="LBS">
    <inertial>
      <origin
        xyz="-0.00678676998851024 0.0106702734987945 0.0591953733266076"
        rpy="0 0 0" />
      <mass
        value="0.11410709738518" />
      <inertia
        ixx="7.89414159986181E-05"
        ixy="1.76562008053687E-21"
        ixz="1.14721099197345E-06"
        iyy="5.15117788979022E-05"
        iyz="3.49030907985095E-21"
        izz="7.8389894275756E-05" />
    </inertial>
    <visual>
      <origin
        xyz="0 0 0"
        rpy="0 0 0" />
      <geometry>
        <mesh
          filename="package://wheelball/meshes/LBS.STL" />
      </geometry>
      <material
        name="">
        <color
          rgba="0.752941176470588 0.752941176470588 0.752941176470588 1" />
      </material>
    </visual>
    <collision>
      <origin
        xyz="0 0 0"
        rpy="0 0 0" />
      <geometry>
        <mesh
          filename="package://wheelball/meshes/LBS.STL" />
      </geometry>
    </collision>
  </link>
  <joint
    name="LBS"
    type="fixed">
    <origin
      xyz="0.23339 0.055845 0"
      rpy="-1.5708 0 0.89134" />
    <parent
      link="base_link" />
    <child
      link="LBS" />
    <axis
      xyz="0 0 0" />
    <limit
      lower="0"
      upper="0"
      effort="0"
      velocity="0" />
  </joint>
  <link
    name="cam1">
    <inertial>
      <origin
        xyz="0.0498359970623519 0.0617836354899649 0.0687226594771384"
        rpy="0 0 0" />
      <mass
        value="0.0436119949785285" />
      <inertia
        ixx="4.2947907827665E-06"
        ixy="-8.85484503942536E-10"
        ixz="-1.01834758012153E-09"
        iyy="2.21058144654638E-05"
        iyz="2.17579332532723E-08"
        izz="2.35707056099602E-05" />
    </inertial>
    <visual>
      <origin
        xyz="0 0 0"
        rpy="0 0 0" />
      <geometry>
        <mesh
          filename="package://wheelball/meshes/cam1.STL" />
      </geometry>
      <material
        name="">
        <color
          rgba="0.792156862745098 0.819607843137255 0.933333333333333 1" />
      </material>
    </visual>
    <collision>
      <origin
        xyz="0 0 0"
        rpy="0 0 0" />
      <geometry>
        <mesh
          filename="package://wheelball/meshes/cam1.STL" />
      </geometry>
    </collision>
  </link>
  <joint
    name="cam1"
    type="fixed">
    <origin
      xyz="-0.049835 -0.022219 0.13322"
      rpy="2.3562 0 0" />
    <parent
      link="base_link" />
    <child
      link="cam1" />
    <axis
      xyz="0 0 0" />
  </joint>
  <link
    name="cam2">
    <inertial>
      <origin
        xyz="0.049835996894939 0.0617836354959193 0.068722659224057"
        rpy="0 0 0" />
      <mass
        value="0.0436119950287128" />
      <inertia
        ixx="4.29479133591154E-06"
        ixy="-8.85791114080511E-10"
        ixz="-1.01813691697105E-09"
        iyy="2.21058141232448E-05"
        iyz="2.17579681215265E-08"
        izz="2.357070580464E-05" />
    </inertial>
    <visual>
      <origin
        xyz="0 0 0"
        rpy="0 0 0" />
      <geometry>
        <mesh
          filename="package://wheelball/meshes/cam2.STL" />
      </geometry>
      <material
        name="">
        <color
          rgba="0.792156862745098 0.819607843137255 0.933333333333333 1" />
      </material>
    </visual>
    <collision>
      <origin
        xyz="0 0 0"
        rpy="0 0 0" />
      <geometry>
        <mesh
          filename="package://wheelball/meshes/cam2.STL" />
      </geometry>
    </collision>
  </link>
  <joint
    name="cam2"
    type="fixed">
    <origin
      xyz="-0.049839 -0.046422 0.10251"
      rpy="1.5708 0 0" />
    <parent
      link="base_link" />
    <child
      link="cam2" />
    <axis
      xyz="0 0 0" />
    <limit
      lower="0"
      upper="0"
      effort="0"
      velocity="0" />
  </joint>
  <link
    name="lidar">
    <inertial>
      <origin
        xyz="-0.0784930224983973 -0.744427433893901 -0.133449662311106"
        rpy="0 0 0" />
      <mass
        value="0.0730845709360323" />
      <inertia
        ixx="1.9580875692911E-05"
        ixy="4.28391199656797E-07"
        ixz="-1.03933596052725E-07"
        iyy="4.14184516232486E-05"
        iyz="-9.42707888853209E-09"
        izz="2.41250079747142E-05" />
    </inertial>
    <visual>
      <origin
        xyz="0 0 0"
        rpy="0 0 0" />
      <geometry>
        <mesh
          filename="package://wheelball/meshes/lidar.STL" />
      </geometry>
      <material
        name="">
        <color
          rgba="0.792156862745098 0.819607843137255 0.933333333333333 1" />
      </material>
    </visual>
    <collision>
      <origin
        xyz="0 0 0"
        rpy="0 0 0" />
      <geometry>
        <mesh
          filename="package://wheelball/meshes/lidar.STL" />
      </geometry>
    </collision>
  </link>
  <joint
    name="lidar"
    type="fixed">
    <origin
      xyz="0.13292 -0.027939 -0.53869"
      rpy="-1.5708 0 -1.5708" />
    <parent
      link="base_link" />
    <child
      link="lidar" />
    <axis
      xyz="0 0 0" />
    <limit
      lower="0"
      upper="0"
      effort="0"
      velocity="0" />
  </joint>
</robot>